{
  "nbformat": 4,
  "nbformat_minor": 0,
  "metadata": {
    "colab": {
      "provenance": [],
      "gpuType": "V28"
    },
    "kernelspec": {
      "name": "python3",
      "display_name": "Python 3"
    },
    "language_info": {
      "name": "python"
    },
    "accelerator": "TPU"
  },
  "cells": [
    {
      "cell_type": "code",
      "execution_count": 38,
      "metadata": {
        "id": "kx7iZmcWp00K"
      },
      "outputs": [],
      "source": [
        "import tensorflow\n",
        "from tensorflow import keras\n",
        "from keras.models import Sequential\n",
        "from keras.layers import Dense, Dropout, Flatten,Embedding, SimpleRNN"
      ]
    },
    {
      "cell_type": "code",
      "source": [
        "from keras.datasets import imdb\n",
        "(X_train,y_train),(X_test,y_test) = imdb.load_data()"
      ],
      "metadata": {
        "colab": {
          "base_uri": "https://localhost:8080/"
        },
        "id": "aqI-ucZeqE17",
        "outputId": "b661bdb7-430c-4a18-e4e5-4ddff5253203"
      },
      "execution_count": 2,
      "outputs": [
        {
          "output_type": "stream",
          "name": "stdout",
          "text": [
            "Downloading data from https://storage.googleapis.com/tensorflow/tf-keras-datasets/imdb.npz\n",
            "17464789/17464789 [==============================] - 0s 0us/step\n"
          ]
        }
      ]
    },
    {
      "cell_type": "code",
      "source": [
        "from keras.utils import pad_sequences\n",
        "\n",
        "\n",
        "\n",
        "X_train = pad_sequences(X_train,padding=\"post\",maxlen=50)\n",
        "X_test = pad_sequences(X_test,padding=\"post\",maxlen=50)"
      ],
      "metadata": {
        "id": "Dkxr-FqjqYJa"
      },
      "execution_count": 39,
      "outputs": []
    },
    {
      "cell_type": "code",
      "source": [
        "X_train.shape"
      ],
      "metadata": {
        "colab": {
          "base_uri": "https://localhost:8080/"
        },
        "id": "YkpqGhqLqbBa",
        "outputId": "91fc941b-7754-4d82-aea9-e7f72dcd5faf"
      },
      "execution_count": 40,
      "outputs": [
        {
          "output_type": "execute_result",
          "data": {
            "text/plain": [
              "(25000, 50)"
            ]
          },
          "metadata": {},
          "execution_count": 40
        }
      ]
    },
    {
      "cell_type": "code",
      "source": [],
      "metadata": {
        "id": "0ZBsL9fOvQsO"
      },
      "execution_count": null,
      "outputs": []
    },
    {
      "cell_type": "code",
      "source": [
        "len(X_train)"
      ],
      "metadata": {
        "colab": {
          "base_uri": "https://localhost:8080/"
        },
        "id": "a9zPUg1jsP26",
        "outputId": "c422595c-8114-4bd9-f8f9-e9c868fef0c2"
      },
      "execution_count": 41,
      "outputs": [
        {
          "output_type": "execute_result",
          "data": {
            "text/plain": [
              "25000"
            ]
          },
          "metadata": {},
          "execution_count": 41
        }
      ]
    },
    {
      "cell_type": "code",
      "source": [
        "model = Sequential()\n",
        "model.add(Embedding(10000,2))\n",
        "model.add(SimpleRNN(32,return_sequences=False))\n",
        "model.add(Dense(1,activation=\"sigmoid\"))\n",
        "\n",
        "model.summary()"
      ],
      "metadata": {
        "colab": {
          "base_uri": "https://localhost:8080/"
        },
        "id": "TUu76VfOr-NX",
        "outputId": "98ca7de0-a92b-4e2a-e09c-bdc5a4edaf1e"
      },
      "execution_count": 42,
      "outputs": [
        {
          "output_type": "stream",
          "name": "stdout",
          "text": [
            "Model: \"sequential_13\"\n",
            "_________________________________________________________________\n",
            " Layer (type)                Output Shape              Param #   \n",
            "=================================================================\n",
            " embedding_13 (Embedding)    (None, None, 2)           20000     \n",
            "                                                                 \n",
            " simple_rnn_7 (SimpleRNN)    (None, 32)                1120      \n",
            "                                                                 \n",
            " dense_7 (Dense)             (None, 1)                 33        \n",
            "                                                                 \n",
            "=================================================================\n",
            "Total params: 21153 (82.63 KB)\n",
            "Trainable params: 21153 (82.63 KB)\n",
            "Non-trainable params: 0 (0.00 Byte)\n",
            "_________________________________________________________________\n"
          ]
        }
      ]
    },
    {
      "cell_type": "code",
      "source": [
        "model.compile(optimizer=\"adam\",loss=\"binary_crossentropy\",metrics=[\"accuracy\"])"
      ],
      "metadata": {
        "id": "hpwnB1l_sqLk"
      },
      "execution_count": 43,
      "outputs": []
    },
    {
      "cell_type": "code",
      "source": [
        "model.fit(X_train,y_train,epochs=5,validation_data=(X_test,y_test))\n",
        "X_test.shape"
      ],
      "metadata": {
        "colab": {
          "base_uri": "https://localhost:8080/",
          "height": 1000
        },
        "id": "pA-4sVwKueDt",
        "outputId": "aca76307-f22b-4d85-9e70-ec7bd25c12e4"
      },
      "execution_count": 47,
      "outputs": [
        {
          "output_type": "stream",
          "name": "stdout",
          "text": [
            "Epoch 1/5\n",
            "565/782 [====================>.........] - ETA: 2s - loss: 0.6933 - accuracy: 0.5008"
          ]
        },
        {
          "output_type": "error",
          "ename": "InvalidArgumentError",
          "evalue": "Graph execution error:\n\nDetected at node sequential_13/embedding_13/embedding_lookup defined at (most recent call last):\n  File \"/usr/lib/python3.10/runpy.py\", line 196, in _run_module_as_main\n\n  File \"/usr/lib/python3.10/runpy.py\", line 86, in _run_code\n\n  File \"/usr/local/lib/python3.10/dist-packages/colab_kernel_launcher.py\", line 37, in <module>\n\n  File \"/usr/local/lib/python3.10/dist-packages/traitlets/config/application.py\", line 992, in launch_instance\n\n  File \"/usr/local/lib/python3.10/dist-packages/ipykernel/kernelapp.py\", line 619, in start\n\n  File \"/usr/local/lib/python3.10/dist-packages/tornado/platform/asyncio.py\", line 195, in start\n\n  File \"/usr/lib/python3.10/asyncio/base_events.py\", line 603, in run_forever\n\n  File \"/usr/lib/python3.10/asyncio/base_events.py\", line 1909, in _run_once\n\n  File \"/usr/lib/python3.10/asyncio/events.py\", line 80, in _run\n\n  File \"/usr/local/lib/python3.10/dist-packages/tornado/ioloop.py\", line 685, in <lambda>\n\n  File \"/usr/local/lib/python3.10/dist-packages/tornado/ioloop.py\", line 738, in _run_callback\n\n  File \"/usr/local/lib/python3.10/dist-packages/tornado/gen.py\", line 825, in inner\n\n  File \"/usr/local/lib/python3.10/dist-packages/tornado/gen.py\", line 786, in run\n\n  File \"/usr/local/lib/python3.10/dist-packages/ipykernel/kernelbase.py\", line 361, in process_one\n\n  File \"/usr/local/lib/python3.10/dist-packages/tornado/gen.py\", line 234, in wrapper\n\n  File \"/usr/local/lib/python3.10/dist-packages/ipykernel/kernelbase.py\", line 261, in dispatch_shell\n\n  File \"/usr/local/lib/python3.10/dist-packages/tornado/gen.py\", line 234, in wrapper\n\n  File \"/usr/local/lib/python3.10/dist-packages/ipykernel/kernelbase.py\", line 539, in execute_request\n\n  File \"/usr/local/lib/python3.10/dist-packages/tornado/gen.py\", line 234, in wrapper\n\n  File \"/usr/local/lib/python3.10/dist-packages/ipykernel/ipkernel.py\", line 302, in do_execute\n\n  File \"/usr/local/lib/python3.10/dist-packages/ipykernel/zmqshell.py\", line 539, in run_cell\n\n  File \"/usr/local/lib/python3.10/dist-packages/IPython/core/interactiveshell.py\", line 2975, in run_cell\n\n  File \"/usr/local/lib/python3.10/dist-packages/IPython/core/interactiveshell.py\", line 3030, in _run_cell\n\n  File \"/usr/local/lib/python3.10/dist-packages/IPython/core/async_helpers.py\", line 78, in _pseudo_sync_runner\n\n  File \"/usr/local/lib/python3.10/dist-packages/IPython/core/interactiveshell.py\", line 3257, in run_cell_async\n\n  File \"/usr/local/lib/python3.10/dist-packages/IPython/core/interactiveshell.py\", line 3473, in run_ast_nodes\n\n  File \"/usr/local/lib/python3.10/dist-packages/IPython/core/interactiveshell.py\", line 3553, in run_code\n\n  File \"<ipython-input-44-969abc459d8f>\", line 1, in <cell line: 1>\n\n  File \"/usr/local/lib/python3.10/dist-packages/keras/src/utils/traceback_utils.py\", line 65, in error_handler\n\n  File \"/usr/local/lib/python3.10/dist-packages/keras/src/engine/training.py\", line 1807, in fit\n\n  File \"/usr/local/lib/python3.10/dist-packages/keras/src/engine/training.py\", line 1401, in train_function\n\n  File \"/usr/local/lib/python3.10/dist-packages/keras/src/engine/training.py\", line 1384, in step_function\n\n  File \"/usr/local/lib/python3.10/dist-packages/keras/src/engine/training.py\", line 1373, in run_step\n\n  File \"/usr/local/lib/python3.10/dist-packages/keras/src/engine/training.py\", line 1150, in train_step\n\n  File \"/usr/local/lib/python3.10/dist-packages/keras/src/utils/traceback_utils.py\", line 65, in error_handler\n\n  File \"/usr/local/lib/python3.10/dist-packages/keras/src/engine/training.py\", line 590, in __call__\n\n  File \"/usr/local/lib/python3.10/dist-packages/keras/src/utils/traceback_utils.py\", line 65, in error_handler\n\n  File \"/usr/local/lib/python3.10/dist-packages/keras/src/engine/base_layer.py\", line 1149, in __call__\n\n  File \"/usr/local/lib/python3.10/dist-packages/keras/src/utils/traceback_utils.py\", line 96, in error_handler\n\n  File \"/usr/local/lib/python3.10/dist-packages/keras/src/engine/sequential.py\", line 398, in call\n\n  File \"/usr/local/lib/python3.10/dist-packages/keras/src/engine/functional.py\", line 515, in call\n\n  File \"/usr/local/lib/python3.10/dist-packages/keras/src/engine/functional.py\", line 672, in _run_internal_graph\n\n  File \"/usr/local/lib/python3.10/dist-packages/keras/src/utils/traceback_utils.py\", line 65, in error_handler\n\n  File \"/usr/local/lib/python3.10/dist-packages/keras/src/engine/base_layer.py\", line 1149, in __call__\n\n  File \"/usr/local/lib/python3.10/dist-packages/keras/src/utils/traceback_utils.py\", line 96, in error_handler\n\n  File \"/usr/local/lib/python3.10/dist-packages/keras/src/layers/core/embedding.py\", line 272, in call\n\nindices[26,8] = 38275 is not in [0, 10000)\n\t [[{{node sequential_13/embedding_13/embedding_lookup}}]] [Op:__inference_train_function_16224]",
          "traceback": [
            "\u001b[0;31m---------------------------------------------------------------------------\u001b[0m",
            "\u001b[0;31mInvalidArgumentError\u001b[0m                      Traceback (most recent call last)",
            "\u001b[0;32m<ipython-input-47-b76cf255d4eb>\u001b[0m in \u001b[0;36m<cell line: 1>\u001b[0;34m()\u001b[0m\n\u001b[0;32m----> 1\u001b[0;31m \u001b[0mmodel\u001b[0m\u001b[0;34m.\u001b[0m\u001b[0mfit\u001b[0m\u001b[0;34m(\u001b[0m\u001b[0mX_train\u001b[0m\u001b[0;34m,\u001b[0m\u001b[0my_train\u001b[0m\u001b[0;34m,\u001b[0m\u001b[0mepochs\u001b[0m\u001b[0;34m=\u001b[0m\u001b[0;36m5\u001b[0m\u001b[0;34m,\u001b[0m\u001b[0mvalidation_data\u001b[0m\u001b[0;34m=\u001b[0m\u001b[0;34m(\u001b[0m\u001b[0mX_test\u001b[0m\u001b[0;34m,\u001b[0m\u001b[0my_test\u001b[0m\u001b[0;34m)\u001b[0m\u001b[0;34m)\u001b[0m\u001b[0;34m\u001b[0m\u001b[0;34m\u001b[0m\u001b[0m\n\u001b[0m\u001b[1;32m      2\u001b[0m \u001b[0mX_test\u001b[0m\u001b[0;34m.\u001b[0m\u001b[0mshape\u001b[0m\u001b[0;34m\u001b[0m\u001b[0;34m\u001b[0m\u001b[0m\n",
            "\u001b[0;32m/usr/local/lib/python3.10/dist-packages/keras/src/utils/traceback_utils.py\u001b[0m in \u001b[0;36merror_handler\u001b[0;34m(*args, **kwargs)\u001b[0m\n\u001b[1;32m     68\u001b[0m             \u001b[0;31m# To get the full stack trace, call:\u001b[0m\u001b[0;34m\u001b[0m\u001b[0;34m\u001b[0m\u001b[0m\n\u001b[1;32m     69\u001b[0m             \u001b[0;31m# `tf.debugging.disable_traceback_filtering()`\u001b[0m\u001b[0;34m\u001b[0m\u001b[0;34m\u001b[0m\u001b[0m\n\u001b[0;32m---> 70\u001b[0;31m             \u001b[0;32mraise\u001b[0m \u001b[0me\u001b[0m\u001b[0;34m.\u001b[0m\u001b[0mwith_traceback\u001b[0m\u001b[0;34m(\u001b[0m\u001b[0mfiltered_tb\u001b[0m\u001b[0;34m)\u001b[0m \u001b[0;32mfrom\u001b[0m \u001b[0;32mNone\u001b[0m\u001b[0;34m\u001b[0m\u001b[0;34m\u001b[0m\u001b[0m\n\u001b[0m\u001b[1;32m     71\u001b[0m         \u001b[0;32mfinally\u001b[0m\u001b[0;34m:\u001b[0m\u001b[0;34m\u001b[0m\u001b[0;34m\u001b[0m\u001b[0m\n\u001b[1;32m     72\u001b[0m             \u001b[0;32mdel\u001b[0m \u001b[0mfiltered_tb\u001b[0m\u001b[0;34m\u001b[0m\u001b[0;34m\u001b[0m\u001b[0m\n",
            "\u001b[0;32m/usr/local/lib/python3.10/dist-packages/tensorflow/python/eager/execute.py\u001b[0m in \u001b[0;36mquick_execute\u001b[0;34m(op_name, num_outputs, inputs, attrs, ctx, name)\u001b[0m\n\u001b[1;32m     51\u001b[0m   \u001b[0;32mtry\u001b[0m\u001b[0;34m:\u001b[0m\u001b[0;34m\u001b[0m\u001b[0;34m\u001b[0m\u001b[0m\n\u001b[1;32m     52\u001b[0m     \u001b[0mctx\u001b[0m\u001b[0;34m.\u001b[0m\u001b[0mensure_initialized\u001b[0m\u001b[0;34m(\u001b[0m\u001b[0;34m)\u001b[0m\u001b[0;34m\u001b[0m\u001b[0;34m\u001b[0m\u001b[0m\n\u001b[0;32m---> 53\u001b[0;31m     tensors = pywrap_tfe.TFE_Py_Execute(ctx._handle, device_name, op_name,\n\u001b[0m\u001b[1;32m     54\u001b[0m                                         inputs, attrs, num_outputs)\n\u001b[1;32m     55\u001b[0m   \u001b[0;32mexcept\u001b[0m \u001b[0mcore\u001b[0m\u001b[0;34m.\u001b[0m\u001b[0m_NotOkStatusException\u001b[0m \u001b[0;32mas\u001b[0m \u001b[0me\u001b[0m\u001b[0;34m:\u001b[0m\u001b[0;34m\u001b[0m\u001b[0;34m\u001b[0m\u001b[0m\n",
            "\u001b[0;31mInvalidArgumentError\u001b[0m: Graph execution error:\n\nDetected at node sequential_13/embedding_13/embedding_lookup defined at (most recent call last):\n  File \"/usr/lib/python3.10/runpy.py\", line 196, in _run_module_as_main\n\n  File \"/usr/lib/python3.10/runpy.py\", line 86, in _run_code\n\n  File \"/usr/local/lib/python3.10/dist-packages/colab_kernel_launcher.py\", line 37, in <module>\n\n  File \"/usr/local/lib/python3.10/dist-packages/traitlets/config/application.py\", line 992, in launch_instance\n\n  File \"/usr/local/lib/python3.10/dist-packages/ipykernel/kernelapp.py\", line 619, in start\n\n  File \"/usr/local/lib/python3.10/dist-packages/tornado/platform/asyncio.py\", line 195, in start\n\n  File \"/usr/lib/python3.10/asyncio/base_events.py\", line 603, in run_forever\n\n  File \"/usr/lib/python3.10/asyncio/base_events.py\", line 1909, in _run_once\n\n  File \"/usr/lib/python3.10/asyncio/events.py\", line 80, in _run\n\n  File \"/usr/local/lib/python3.10/dist-packages/tornado/ioloop.py\", line 685, in <lambda>\n\n  File \"/usr/local/lib/python3.10/dist-packages/tornado/ioloop.py\", line 738, in _run_callback\n\n  File \"/usr/local/lib/python3.10/dist-packages/tornado/gen.py\", line 825, in inner\n\n  File \"/usr/local/lib/python3.10/dist-packages/tornado/gen.py\", line 786, in run\n\n  File \"/usr/local/lib/python3.10/dist-packages/ipykernel/kernelbase.py\", line 361, in process_one\n\n  File \"/usr/local/lib/python3.10/dist-packages/tornado/gen.py\", line 234, in wrapper\n\n  File \"/usr/local/lib/python3.10/dist-packages/ipykernel/kernelbase.py\", line 261, in dispatch_shell\n\n  File \"/usr/local/lib/python3.10/dist-packages/tornado/gen.py\", line 234, in wrapper\n\n  File \"/usr/local/lib/python3.10/dist-packages/ipykernel/kernelbase.py\", line 539, in execute_request\n\n  File \"/usr/local/lib/python3.10/dist-packages/tornado/gen.py\", line 234, in wrapper\n\n  File \"/usr/local/lib/python3.10/dist-packages/ipykernel/ipkernel.py\", line 302, in do_execute\n\n  File \"/usr/local/lib/python3.10/dist-packages/ipykernel/zmqshell.py\", line 539, in run_cell\n\n  File \"/usr/local/lib/python3.10/dist-packages/IPython/core/interactiveshell.py\", line 2975, in run_cell\n\n  File \"/usr/local/lib/python3.10/dist-packages/IPython/core/interactiveshell.py\", line 3030, in _run_cell\n\n  File \"/usr/local/lib/python3.10/dist-packages/IPython/core/async_helpers.py\", line 78, in _pseudo_sync_runner\n\n  File \"/usr/local/lib/python3.10/dist-packages/IPython/core/interactiveshell.py\", line 3257, in run_cell_async\n\n  File \"/usr/local/lib/python3.10/dist-packages/IPython/core/interactiveshell.py\", line 3473, in run_ast_nodes\n\n  File \"/usr/local/lib/python3.10/dist-packages/IPython/core/interactiveshell.py\", line 3553, in run_code\n\n  File \"<ipython-input-44-969abc459d8f>\", line 1, in <cell line: 1>\n\n  File \"/usr/local/lib/python3.10/dist-packages/keras/src/utils/traceback_utils.py\", line 65, in error_handler\n\n  File \"/usr/local/lib/python3.10/dist-packages/keras/src/engine/training.py\", line 1807, in fit\n\n  File \"/usr/local/lib/python3.10/dist-packages/keras/src/engine/training.py\", line 1401, in train_function\n\n  File \"/usr/local/lib/python3.10/dist-packages/keras/src/engine/training.py\", line 1384, in step_function\n\n  File \"/usr/local/lib/python3.10/dist-packages/keras/src/engine/training.py\", line 1373, in run_step\n\n  File \"/usr/local/lib/python3.10/dist-packages/keras/src/engine/training.py\", line 1150, in train_step\n\n  File \"/usr/local/lib/python3.10/dist-packages/keras/src/utils/traceback_utils.py\", line 65, in error_handler\n\n  File \"/usr/local/lib/python3.10/dist-packages/keras/src/engine/training.py\", line 590, in __call__\n\n  File \"/usr/local/lib/python3.10/dist-packages/keras/src/utils/traceback_utils.py\", line 65, in error_handler\n\n  File \"/usr/local/lib/python3.10/dist-packages/keras/src/engine/base_layer.py\", line 1149, in __call__\n\n  File \"/usr/local/lib/python3.10/dist-packages/keras/src/utils/traceback_utils.py\", line 96, in error_handler\n\n  File \"/usr/local/lib/python3.10/dist-packages/keras/src/engine/sequential.py\", line 398, in call\n\n  File \"/usr/local/lib/python3.10/dist-packages/keras/src/engine/functional.py\", line 515, in call\n\n  File \"/usr/local/lib/python3.10/dist-packages/keras/src/engine/functional.py\", line 672, in _run_internal_graph\n\n  File \"/usr/local/lib/python3.10/dist-packages/keras/src/utils/traceback_utils.py\", line 65, in error_handler\n\n  File \"/usr/local/lib/python3.10/dist-packages/keras/src/engine/base_layer.py\", line 1149, in __call__\n\n  File \"/usr/local/lib/python3.10/dist-packages/keras/src/utils/traceback_utils.py\", line 96, in error_handler\n\n  File \"/usr/local/lib/python3.10/dist-packages/keras/src/layers/core/embedding.py\", line 272, in call\n\nindices[26,8] = 38275 is not in [0, 10000)\n\t [[{{node sequential_13/embedding_13/embedding_lookup}}]] [Op:__inference_train_function_16224]"
          ]
        }
      ]
    },
    {
      "cell_type": "code",
      "source": [
        "print(X_train.shape)\n",
        "print(y_train.shape)\n",
        "print(X_test.shape)\n",
        "print(y_test.shape)"
      ],
      "metadata": {
        "colab": {
          "base_uri": "https://localhost:8080/"
        },
        "id": "GyvtuSJFugBv",
        "outputId": "72026676-dd81-4472-a48d-4f7fba909b0a"
      },
      "execution_count": 46,
      "outputs": [
        {
          "output_type": "stream",
          "name": "stdout",
          "text": [
            "(25000, 50)\n",
            "(25000,)\n",
            "(25000, 50)\n",
            "(25000,)\n"
          ]
        }
      ]
    },
    {
      "cell_type": "code",
      "source": [],
      "metadata": {
        "id": "kO40jnKzvnSg"
      },
      "execution_count": null,
      "outputs": []
    }
  ]
}